<?xml version='1.0' encoding='utf-8'?>
<robot name="partnet_80d86a40527fd0a7edd4171cd40b3feb">
	<link name="base" />
	<link name="link_0">
		<visual name="movable_part-21">
			<origin xyz="0 0.7912494478839914 0.1292278414417505" />
			<geometry>
				<mesh filename="textured_objs/original-6.obj" />
			</geometry>
		</visual>
		<collision>
			<origin xyz="0 0.7912494478839914 0.1292278414417505" />
			<geometry>
				<mesh filename="textured_objs/original-6.obj" />
			</geometry>
		</collision>
	</link>
	<joint name="joint_0" type="revolute">
		<origin xyz="0 -0.7912494478839914 -0.1292278414417505" />
		<axis xyz="-1 0 0" />
		<child link="link_0" />
		<parent link="link_1" />
		<limit lower="0.0" upper="0.26389378290154264" />
	</joint>
	<link name="link_1">
		<visual name="other_leaf-24">
			<origin xyz="0 0 0" />
			<geometry>
				<mesh filename="textured_objs/original-14.obj" />
			</geometry>
		</visual>
		<visual name="other_leaf-24">
			<origin xyz="0 0 0" />
			<geometry>
				<mesh filename="textured_objs/original-15.obj" />
			</geometry>
		</visual>
		<visual name="other_leaf-24">
			<origin xyz="0 0 0" />
			<geometry>
				<mesh filename="textured_objs/original-16.obj" />
			</geometry>
		</visual>
		<visual name="other_leaf-24">
			<origin xyz="0 0 0" />
			<geometry>
				<mesh filename="textured_objs/original-17.obj" />
			</geometry>
		</visual>
		<visual name="other_leaf-24">
			<origin xyz="0 0 0" />
			<geometry>
				<mesh filename="textured_objs/original-18.obj" />
			</geometry>
		</visual>
		<visual name="other_leaf-24">
			<origin xyz="0 0 0" />
			<geometry>
				<mesh filename="textured_objs/original-19.obj" />
			</geometry>
		</visual>
		<visual name="other_leaf-24">
			<origin xyz="0 0 0" />
			<geometry>
				<mesh filename="textured_objs/original-20.obj" />
			</geometry>
		</visual>
		<visual name="other_leaf-24">
			<origin xyz="0 0 0" />
			<geometry>
				<mesh filename="textured_objs/original-22.obj" />
			</geometry>
		</visual>
		<visual name="other_leaf-24">
			<origin xyz="0 0 0" />
			<geometry>
				<mesh filename="textured_objs/original-21.obj" />
			</geometry>
		</visual>
		<visual name="other_leaf-24">
			<origin xyz="0 0 0" />
			<geometry>
				<mesh filename="textured_objs/original-23.obj" />
			</geometry>
		</visual>
		<visual name="other_leaf-24">
			<origin xyz="0 0 0" />
			<geometry>
				<mesh filename="textured_objs/original-24.obj" />
			</geometry>
		</visual>
		<visual name="lamp_pole-15">
			<origin xyz="0 0 0" />
			<geometry>
				<mesh filename="textured_objs/original-10.obj" />
			</geometry>
		</visual>
		<visual name="connector-9">
			<origin xyz="0 0 0" />
			<geometry>
				<mesh filename="textured_objs/original-11.obj" />
			</geometry>
		</visual>
		<visual name="lamp_base_part-17">
			<origin xyz="0 0 0" />
			<geometry>
				<mesh filename="textured_objs/original-25.obj" />
			</geometry>
		</visual>
		<visual name="fixed_part-22">
			<origin xyz="0 0 0" />
			<geometry>
				<mesh filename="textured_objs/original-5.obj" />
			</geometry>
		</visual>
		<collision>
			<origin xyz="0 0 0" />
			<geometry>
				<mesh filename="textured_objs/original-14.obj" />
			</geometry>
		</collision>
		<collision>
			<origin xyz="0 0 0" />
			<geometry>
				<mesh filename="textured_objs/original-15.obj" />
			</geometry>
		</collision>
		<collision>
			<origin xyz="0 0 0" />
			<geometry>
				<mesh filename="textured_objs/original-16.obj" />
			</geometry>
		</collision>
		<collision>
			<origin xyz="0 0 0" />
			<geometry>
				<mesh filename="textured_objs/original-17.obj" />
			</geometry>
		</collision>
		<collision>
			<origin xyz="0 0 0" />
			<geometry>
				<mesh filename="textured_objs/original-18.obj" />
			</geometry>
		</collision>
		<collision>
			<origin xyz="0 0 0" />
			<geometry>
				<mesh filename="textured_objs/original-19.obj" />
			</geometry>
		</collision>
		<collision>
			<origin xyz="0 0 0" />
			<geometry>
				<mesh filename="textured_objs/original-20.obj" />
			</geometry>
		</collision>
		<collision>
			<origin xyz="0 0 0" />
			<geometry>
				<mesh filename="textured_objs/original-22.obj" />
			</geometry>
		</collision>
		<collision>
			<origin xyz="0 0 0" />
			<geometry>
				<mesh filename="textured_objs/original-21.obj" />
			</geometry>
		</collision>
		<collision>
			<origin xyz="0 0 0" />
			<geometry>
				<mesh filename="textured_objs/original-23.obj" />
			</geometry>
		</collision>
		<collision>
			<origin xyz="0 0 0" />
			<geometry>
				<mesh filename="textured_objs/original-24.obj" />
			</geometry>
		</collision>
		<collision>
			<origin xyz="0 0 0" />
			<geometry>
				<mesh filename="textured_objs/original-10.obj" />
			</geometry>
		</collision>
		<collision>
			<origin xyz="0 0 0" />
			<geometry>
				<mesh filename="textured_objs/original-11.obj" />
			</geometry>
		</collision>
		<collision>
			<origin xyz="0 0 0" />
			<geometry>
				<mesh filename="textured_objs/original-25.obj" />
			</geometry>
		</collision>
		<collision>
			<origin xyz="0 0 0" />
			<geometry>
				<mesh filename="textured_objs/original-5.obj" />
			</geometry>
		</collision>
	</link>
	<joint name="joint_1" type="fixed">
		<origin rpy="1.570796326794897 0 -1.570796326794897" xyz="0 0 0" />
		<child link="link_1" />
		<parent link="base" />
	</joint>
	<link name="link_2">
		<visual name="lamp_arm_straight_bar-7">
			<origin xyz="0.004340000000000001 0 0.38319" />
			<geometry>
				<mesh filename="textured_objs/original-3.obj" />
			</geometry>
		</visual>
		<visual name="lamp_shade-13">
			<origin xyz="0.004340000000000001 0 0.38319" />
			<geometry>
				<mesh filename="textured_objs/new-3.obj" />
			</geometry>
		</visual>
		<visual name="light_socket-11">
			<origin xyz="0.004340000000000001 0 0.38319" />
			<geometry>
				<mesh filename="textured_objs/new-0.obj" />
			</geometry>
		</visual>
		<visual name="light_socket-11">
			<origin xyz="0.004340000000000001 0 0.38319" />
			<geometry>
				<mesh filename="textured_objs/original-29.obj" />
			</geometry>
		</visual>
		<visual name="light_socket-11">
			<origin xyz="0.004340000000000001 0 0.38319" />
			<geometry>
				<mesh filename="textured_objs/original-26.obj" />
			</geometry>
		</visual>
		<visual name="light_bulb-12">
			<origin xyz="0.004340000000000001 0 0.38319" />
			<geometry>
				<mesh filename="textured_objs/new-1.obj" />
			</geometry>
		</visual>
		<visual name="lamp_cover_holder-14">
			<origin xyz="0.004340000000000001 0 0.38319" />
			<geometry>
				<mesh filename="textured_objs/new-2.obj" />
			</geometry>
		</visual>
		<collision>
			<origin xyz="0.004340000000000001 0 0.38319" />
			<geometry>
				<mesh filename="textured_objs/original-3.obj" />
			</geometry>
		</collision>
		<collision>
			<origin xyz="0.004340000000000001 0 0.38319" />
			<geometry>
				<mesh filename="textured_objs/new-3.obj" />
			</geometry>
		</collision>
		<collision>
			<origin xyz="0.004340000000000001 0 0.38319" />
			<geometry>
				<mesh filename="textured_objs/new-0.obj" />
			</geometry>
		</collision>
		<collision>
			<origin xyz="0.004340000000000001 0 0.38319" />
			<geometry>
				<mesh filename="textured_objs/original-29.obj" />
			</geometry>
		</collision>
		<collision>
			<origin xyz="0.004340000000000001 0 0.38319" />
			<geometry>
				<mesh filename="textured_objs/original-26.obj" />
			</geometry>
		</collision>
		<collision>
			<origin xyz="0.004340000000000001 0 0.38319" />
			<geometry>
				<mesh filename="textured_objs/new-1.obj" />
			</geometry>
		</collision>
		<collision>
			<origin xyz="0.004340000000000001 0 0.38319" />
			<geometry>
				<mesh filename="textured_objs/new-2.obj" />
			</geometry>
		</collision>
	</link>
	<joint name="joint_2" type="continuous">
		<origin xyz="-0.004340000000000001 0 -0.38319" />
		<axis xyz="0 1 0" />
		<child link="link_2" />
		<parent link="link_1" />
	</joint>
</robot>