<?xml version='1.0' encoding='utf-8'?>
<robot name="partnet_588d0d66-e5c6-40aa-ba9d-6b34085c60a8">
	<link name="base" />
	<link name="link_0">
		<visual name="sphere-1">
			<origin xyz="0.012146194794789206 0 -0.008527805205210792" />
			<geometry>
				<mesh filename="textured_objs/original-8.obj" />
			</geometry>
		</visual>
		<collision>
			<origin xyz="0.012146194794789206 0 -0.008527805205210792" />
			<geometry>
				<mesh filename="textured_objs/original-8.obj" />
			</geometry>
		</collision>
	</link>
	<joint name="joint_0" type="continuous">
		<origin xyz="-0.012146194794789206 0 0.008527805205210792" />
		<axis xyz="0 1 0" />
		<child link="link_0" />
		<parent link="link_1" />
	</joint>
	<link name="link_1">
		<visual name="base_body-2">
			<origin xyz="0 0 0" />
			<geometry>
				<mesh filename="textured_objs/original-4.obj" />
			</geometry>
		</visual>
		<visual name="base_body-2">
			<origin xyz="0 0 0" />
			<geometry>
				<mesh filename="textured_objs/original-2.obj" />
			</geometry>
		</visual>
		<visual name="base_body-2">
			<origin xyz="0 0 0" />
			<geometry>
				<mesh filename="textured_objs/original-5.obj" />
			</geometry>
		</visual>
		<visual name="base_body-2">
			<origin xyz="0 0 0" />
			<geometry>
				<mesh filename="textured_objs/original-6.obj" />
			</geometry>
		</visual>
		<visual name="base_body-2">
			<origin xyz="0 0 0" />
			<geometry>
				<mesh filename="textured_objs/original-7.obj" />
			</geometry>
		</visual>
		<collision>
			<origin xyz="0 0 0" />
			<geometry>
				<mesh filename="textured_objs/original-4.obj" />
			</geometry>
		</collision>
		<collision>
			<origin xyz="0 0 0" />
			<geometry>
				<mesh filename="textured_objs/original-2.obj" />
			</geometry>
		</collision>
		<collision>
			<origin xyz="0 0 0" />
			<geometry>
				<mesh filename="textured_objs/original-5.obj" />
			</geometry>
		</collision>
		<collision>
			<origin xyz="0 0 0" />
			<geometry>
				<mesh filename="textured_objs/original-6.obj" />
			</geometry>
		</collision>
		<collision>
			<origin xyz="0 0 0" />
			<geometry>
				<mesh filename="textured_objs/original-7.obj" />
			</geometry>
		</collision>
	</link>
	<joint name="joint_1" type="fixed">
		<origin rpy="1.570796326794897 0 -1.570796326794897" xyz="0 0 0" />
		<child link="link_1" />
		<parent link="base" />
	</joint>
</robot>