<?xml version='1.0' encoding='utf-8'?>
<robot name="partnet_f643a64a4e38723f73c478529c40c4e6">
	<link name="base" />
	<link name="link_0">
		<visual name="drawer_front-92">
			<origin xyz="0 0 0" />
			<geometry>
				<mesh filename="textured_objs/original-5.obj" />
			</geometry>
		</visual>
		<visual name="drawer_side-93">
			<origin xyz="0 0 0" />
			<geometry>
				<mesh filename="textured_objs/original-7.obj" />
			</geometry>
		</visual>
		<visual name="drawer_side-94">
			<origin xyz="0 0 0" />
			<geometry>
				<mesh filename="textured_objs/original-8.obj" />
			</geometry>
		</visual>
		<visual name="drawer_back-95">
			<origin xyz="0 0 0" />
			<geometry>
				<mesh filename="textured_objs/original-6.obj" />
			</geometry>
		</visual>
		<visual name="drawer_bottom-96">
			<origin xyz="0 0 0" />
			<geometry>
				<mesh filename="textured_objs/original-9.obj" />
			</geometry>
		</visual>
		<visual name="other_leaf-118">
			<origin xyz="0 0 0" />
			<geometry>
				<mesh filename="textured_objs/original-3.obj" />
			</geometry>
		</visual>
		<visual name="other_leaf-118">
			<origin xyz="0 0 0" />
			<geometry>
				<mesh filename="textured_objs/original-4.obj" />
			</geometry>
		</visual>
		<collision>
			<origin xyz="0 0 0" />
			<geometry>
				<mesh filename="textured_objs/original-5.obj" />
			</geometry>
		</collision>
		<collision>
			<origin xyz="0 0 0" />
			<geometry>
				<mesh filename="textured_objs/original-7.obj" />
			</geometry>
		</collision>
		<collision>
			<origin xyz="0 0 0" />
			<geometry>
				<mesh filename="textured_objs/original-8.obj" />
			</geometry>
		</collision>
		<collision>
			<origin xyz="0 0 0" />
			<geometry>
				<mesh filename="textured_objs/original-6.obj" />
			</geometry>
		</collision>
		<collision>
			<origin xyz="0 0 0" />
			<geometry>
				<mesh filename="textured_objs/original-9.obj" />
			</geometry>
		</collision>
		<collision>
			<origin xyz="0 0 0" />
			<geometry>
				<mesh filename="textured_objs/original-3.obj" />
			</geometry>
		</collision>
		<collision>
			<origin xyz="0 0 0" />
			<geometry>
				<mesh filename="textured_objs/original-4.obj" />
			</geometry>
		</collision>
	</link>
	<joint name="joint_0" type="prismatic">
		<origin xyz="0 0 0" />
		<axis xyz="0 0 1" />
		<child link="link_0" />
		<parent link="link_6" />
		<limit lower="-0.08800000000000008" upper="0.6400000000000001" />
	</joint>
	<link name="link_1">
		<visual name="drawer_front-84">
			<origin xyz="0 0 0" />
			<geometry>
				<mesh filename="textured_objs/original-83.obj" />
			</geometry>
		</visual>
		<visual name="drawer_side-85">
			<origin xyz="0 0 0" />
			<geometry>
				<mesh filename="textured_objs/original-88.obj" />
			</geometry>
		</visual>
		<visual name="drawer_side-86">
			<origin xyz="0 0 0" />
			<geometry>
				<mesh filename="textured_objs/original-86.obj" />
			</geometry>
		</visual>
		<visual name="drawer_back-87">
			<origin xyz="0 0 0" />
			<geometry>
				<mesh filename="textured_objs/original-87.obj" />
			</geometry>
		</visual>
		<visual name="drawer_bottom-88">
			<origin xyz="0 0 0" />
			<geometry>
				<mesh filename="textured_objs/original-89.obj" />
			</geometry>
		</visual>
		<visual name="handle-83">
			<origin xyz="0 0 0" />
			<geometry>
				<mesh filename="textured_objs/original-82.obj" />
			</geometry>
		</visual>
		<visual name="handle-83">
			<origin xyz="0 0 0" />
			<geometry>
				<mesh filename="textured_objs/original-81.obj" />
			</geometry>
		</visual>
		<collision>
			<origin xyz="0 0 0" />
			<geometry>
				<mesh filename="textured_objs/original-83.obj" />
			</geometry>
		</collision>
		<collision>
			<origin xyz="0 0 0" />
			<geometry>
				<mesh filename="textured_objs/original-88.obj" />
			</geometry>
		</collision>
		<collision>
			<origin xyz="0 0 0" />
			<geometry>
				<mesh filename="textured_objs/original-86.obj" />
			</geometry>
		</collision>
		<collision>
			<origin xyz="0 0 0" />
			<geometry>
				<mesh filename="textured_objs/original-87.obj" />
			</geometry>
		</collision>
		<collision>
			<origin xyz="0 0 0" />
			<geometry>
				<mesh filename="textured_objs/original-89.obj" />
			</geometry>
		</collision>
		<collision>
			<origin xyz="0 0 0" />
			<geometry>
				<mesh filename="textured_objs/original-82.obj" />
			</geometry>
		</collision>
		<collision>
			<origin xyz="0 0 0" />
			<geometry>
				<mesh filename="textured_objs/original-81.obj" />
			</geometry>
		</collision>
	</link>
	<joint name="joint_1" type="prismatic">
		<origin xyz="0 0 0" />
		<axis xyz="0 0 1" />
		<child link="link_1" />
		<parent link="link_6" />
		<limit lower="-0.06000000000000005" upper="0.6840000000000002" />
	</joint>
	<link name="link_2">
		<visual name="drawer_front-77">
			<origin xyz="0 0 0" />
			<geometry>
				<mesh filename="textured_objs/original-46.obj" />
			</geometry>
		</visual>
		<visual name="drawer_side-78">
			<origin xyz="0 0 0" />
			<geometry>
				<mesh filename="textured_objs/original-51.obj" />
			</geometry>
		</visual>
		<visual name="drawer_side-79">
			<origin xyz="0 0 0" />
			<geometry>
				<mesh filename="textured_objs/original-49.obj" />
			</geometry>
		</visual>
		<visual name="drawer_back-80">
			<origin xyz="0 0 0" />
			<geometry>
				<mesh filename="textured_objs/original-50.obj" />
			</geometry>
		</visual>
		<visual name="drawer_bottom-81">
			<origin xyz="0 0 0" />
			<geometry>
				<mesh filename="textured_objs/original-52.obj" />
			</geometry>
		</visual>
		<visual name="handle-76">
			<origin xyz="0 0 0" />
			<geometry>
				<mesh filename="textured_objs/original-45.obj" />
			</geometry>
		</visual>
		<visual name="handle-76">
			<origin xyz="0 0 0" />
			<geometry>
				<mesh filename="textured_objs/original-44.obj" />
			</geometry>
		</visual>
		<collision>
			<origin xyz="0 0 0" />
			<geometry>
				<mesh filename="textured_objs/original-46.obj" />
			</geometry>
		</collision>
		<collision>
			<origin xyz="0 0 0" />
			<geometry>
				<mesh filename="textured_objs/original-51.obj" />
			</geometry>
		</collision>
		<collision>
			<origin xyz="0 0 0" />
			<geometry>
				<mesh filename="textured_objs/original-49.obj" />
			</geometry>
		</collision>
		<collision>
			<origin xyz="0 0 0" />
			<geometry>
				<mesh filename="textured_objs/original-50.obj" />
			</geometry>
		</collision>
		<collision>
			<origin xyz="0 0 0" />
			<geometry>
				<mesh filename="textured_objs/original-52.obj" />
			</geometry>
		</collision>
		<collision>
			<origin xyz="0 0 0" />
			<geometry>
				<mesh filename="textured_objs/original-45.obj" />
			</geometry>
		</collision>
		<collision>
			<origin xyz="0 0 0" />
			<geometry>
				<mesh filename="textured_objs/original-44.obj" />
			</geometry>
		</collision>
	</link>
	<joint name="joint_2" type="prismatic">
		<origin xyz="0 0 0" />
		<axis xyz="0 0 1" />
		<child link="link_2" />
		<parent link="link_6" />
		<limit lower="0" upper="0.7959999999999998" />
	</joint>
	<link name="link_3">
		<visual name="drawer_front-70">
			<origin xyz="0 0 0" />
			<geometry>
				<mesh filename="textured_objs/original-35.obj" />
			</geometry>
		</visual>
		<visual name="drawer_side-71">
			<origin xyz="0 0 0" />
			<geometry>
				<mesh filename="textured_objs/original-40.obj" />
			</geometry>
		</visual>
		<visual name="drawer_side-72">
			<origin xyz="0 0 0" />
			<geometry>
				<mesh filename="textured_objs/original-38.obj" />
			</geometry>
		</visual>
		<visual name="drawer_back-73">
			<origin xyz="0 0 0" />
			<geometry>
				<mesh filename="textured_objs/original-39.obj" />
			</geometry>
		</visual>
		<visual name="drawer_bottom-74">
			<origin xyz="0 0 0" />
			<geometry>
				<mesh filename="textured_objs/original-41.obj" />
			</geometry>
		</visual>
		<visual name="handle-69">
			<origin xyz="0 0 0" />
			<geometry>
				<mesh filename="textured_objs/original-33.obj" />
			</geometry>
		</visual>
		<visual name="handle-69">
			<origin xyz="0 0 0" />
			<geometry>
				<mesh filename="textured_objs/original-34.obj" />
			</geometry>
		</visual>
		<collision>
			<origin xyz="0 0 0" />
			<geometry>
				<mesh filename="textured_objs/original-35.obj" />
			</geometry>
		</collision>
		<collision>
			<origin xyz="0 0 0" />
			<geometry>
				<mesh filename="textured_objs/original-40.obj" />
			</geometry>
		</collision>
		<collision>
			<origin xyz="0 0 0" />
			<geometry>
				<mesh filename="textured_objs/original-38.obj" />
			</geometry>
		</collision>
		<collision>
			<origin xyz="0 0 0" />
			<geometry>
				<mesh filename="textured_objs/original-39.obj" />
			</geometry>
		</collision>
		<collision>
			<origin xyz="0 0 0" />
			<geometry>
				<mesh filename="textured_objs/original-41.obj" />
			</geometry>
		</collision>
		<collision>
			<origin xyz="0 0 0" />
			<geometry>
				<mesh filename="textured_objs/original-33.obj" />
			</geometry>
		</collision>
		<collision>
			<origin xyz="0 0 0" />
			<geometry>
				<mesh filename="textured_objs/original-34.obj" />
			</geometry>
		</collision>
	</link>
	<joint name="joint_3" type="prismatic">
		<origin xyz="0 0 0" />
		<axis xyz="0 0 1" />
		<child link="link_3" />
		<parent link="link_6" />
		<limit lower="-0.1399999999999999" upper="0.6320000000000001" />
	</joint>
	<link name="link_4">
		<visual name="drawer_front-61">
			<origin xyz="0 0 0" />
			<geometry>
				<mesh filename="textured_objs/original-74.obj" />
			</geometry>
		</visual>
		<visual name="drawer_side-62">
			<origin xyz="0 0 0" />
			<geometry>
				<mesh filename="textured_objs/original-75.obj" />
			</geometry>
		</visual>
		<visual name="drawer_side-63">
			<origin xyz="0 0 0" />
			<geometry>
				<mesh filename="textured_objs/original-77.obj" />
			</geometry>
		</visual>
		<visual name="drawer_back-64">
			<origin xyz="0 0 0" />
			<geometry>
				<mesh filename="textured_objs/original-76.obj" />
			</geometry>
		</visual>
		<visual name="drawer_bottom-65">
			<origin xyz="0 0 0" />
			<geometry>
				<mesh filename="textured_objs/original-78.obj" />
			</geometry>
		</visual>
		<visual name="handle-59">
			<origin xyz="0 0 0" />
			<geometry>
				<mesh filename="textured_objs/original-69.obj" />
			</geometry>
		</visual>
		<visual name="handle-59">
			<origin xyz="0 0 0" />
			<geometry>
				<mesh filename="textured_objs/original-68.obj" />
			</geometry>
		</visual>
		<visual name="handle-60">
			<origin xyz="0 0 0" />
			<geometry>
				<mesh filename="textured_objs/original-73.obj" />
			</geometry>
		</visual>
		<visual name="handle-60">
			<origin xyz="0 0 0" />
			<geometry>
				<mesh filename="textured_objs/original-72.obj" />
			</geometry>
		</visual>
		<collision>
			<origin xyz="0 0 0" />
			<geometry>
				<mesh filename="textured_objs/original-74.obj" />
			</geometry>
		</collision>
		<collision>
			<origin xyz="0 0 0" />
			<geometry>
				<mesh filename="textured_objs/original-75.obj" />
			</geometry>
		</collision>
		<collision>
			<origin xyz="0 0 0" />
			<geometry>
				<mesh filename="textured_objs/original-77.obj" />
			</geometry>
		</collision>
		<collision>
			<origin xyz="0 0 0" />
			<geometry>
				<mesh filename="textured_objs/original-76.obj" />
			</geometry>
		</collision>
		<collision>
			<origin xyz="0 0 0" />
			<geometry>
				<mesh filename="textured_objs/original-78.obj" />
			</geometry>
		</collision>
		<collision>
			<origin xyz="0 0 0" />
			<geometry>
				<mesh filename="textured_objs/original-69.obj" />
			</geometry>
		</collision>
		<collision>
			<origin xyz="0 0 0" />
			<geometry>
				<mesh filename="textured_objs/original-68.obj" />
			</geometry>
		</collision>
		<collision>
			<origin xyz="0 0 0" />
			<geometry>
				<mesh filename="textured_objs/original-73.obj" />
			</geometry>
		</collision>
		<collision>
			<origin xyz="0 0 0" />
			<geometry>
				<mesh filename="textured_objs/original-72.obj" />
			</geometry>
		</collision>
	</link>
	<joint name="joint_4" type="prismatic">
		<origin xyz="0 0 0" />
		<axis xyz="0 0 1" />
		<child link="link_4" />
		<parent link="link_6" />
		<limit lower="-0.07600000000000007" upper="0.7120000000000002" />
	</joint>
	<link name="link_5">
		<visual name="drawer_front-39">
			<origin xyz="0 0 0" />
			<geometry>
				<mesh filename="textured_objs/original-57.obj" />
			</geometry>
		</visual>
		<visual name="drawer_side-40">
			<origin xyz="0 0 0" />
			<geometry>
				<mesh filename="textured_objs/original-60.obj" />
			</geometry>
		</visual>
		<visual name="drawer_side-41">
			<origin xyz="0 0 0" />
			<geometry>
				<mesh filename="textured_objs/original-62.obj" />
			</geometry>
		</visual>
		<visual name="drawer_back-42">
			<origin xyz="0 0 0" />
			<geometry>
				<mesh filename="textured_objs/original-61.obj" />
			</geometry>
		</visual>
		<visual name="drawer_bottom-43">
			<origin xyz="0 0 0" />
			<geometry>
				<mesh filename="textured_objs/original-63.obj" />
			</geometry>
		</visual>
		<visual name="handle-38">
			<origin xyz="0 0 0" />
			<geometry>
				<mesh filename="textured_objs/original-56.obj" />
			</geometry>
		</visual>
		<visual name="handle-38">
			<origin xyz="0 0 0" />
			<geometry>
				<mesh filename="textured_objs/original-55.obj" />
			</geometry>
		</visual>
		<collision>
			<origin xyz="0 0 0" />
			<geometry>
				<mesh filename="textured_objs/original-57.obj" />
			</geometry>
		</collision>
		<collision>
			<origin xyz="0 0 0" />
			<geometry>
				<mesh filename="textured_objs/original-60.obj" />
			</geometry>
		</collision>
		<collision>
			<origin xyz="0 0 0" />
			<geometry>
				<mesh filename="textured_objs/original-62.obj" />
			</geometry>
		</collision>
		<collision>
			<origin xyz="0 0 0" />
			<geometry>
				<mesh filename="textured_objs/original-61.obj" />
			</geometry>
		</collision>
		<collision>
			<origin xyz="0 0 0" />
			<geometry>
				<mesh filename="textured_objs/original-63.obj" />
			</geometry>
		</collision>
		<collision>
			<origin xyz="0 0 0" />
			<geometry>
				<mesh filename="textured_objs/original-56.obj" />
			</geometry>
		</collision>
		<collision>
			<origin xyz="0 0 0" />
			<geometry>
				<mesh filename="textured_objs/original-55.obj" />
			</geometry>
		</collision>
	</link>
	<joint name="joint_5" type="prismatic">
		<origin xyz="0 0 0" />
		<axis xyz="0 0 1" />
		<child link="link_5" />
		<parent link="link_6" />
		<limit lower="-0.08800000000000008" upper="0.6960000000000002" />
	</joint>
	<link name="link_6">
		<visual name="board-67">
			<origin xyz="0 0 0" />
			<geometry>
				<mesh filename="textured_objs/original-1.obj" />
			</geometry>
		</visual>
		<visual name="leg-19">
			<origin xyz="0 0 0" />
			<geometry>
				<mesh filename="textured_objs/original-27.obj" />
			</geometry>
		</visual>
		<visual name="leg-20">
			<origin xyz="0 0 0" />
			<geometry>
				<mesh filename="textured_objs/original-29.obj" />
			</geometry>
		</visual>
		<visual name="leg-21">
			<origin xyz="0 0 0" />
			<geometry>
				<mesh filename="textured_objs/original-23.obj" />
			</geometry>
		</visual>
		<visual name="leg-22">
			<origin xyz="0 0 0" />
			<geometry>
				<mesh filename="textured_objs/original-20.obj" />
			</geometry>
		</visual>
		<visual name="leg-23">
			<origin xyz="0 0 0" />
			<geometry>
				<mesh filename="textured_objs/original-25.obj" />
			</geometry>
		</visual>
		<visual name="leg-24">
			<origin xyz="0 0 0" />
			<geometry>
				<mesh filename="textured_objs/original-30.obj" />
			</geometry>
		</visual>
		<visual name="back_panel-32">
			<origin xyz="0 0 0" />
			<geometry>
				<mesh filename="textured_objs/original-28.obj" />
			</geometry>
		</visual>
		<visual name="vertical_side_panel-33">
			<origin xyz="0 0 0" />
			<geometry>
				<mesh filename="textured_objs/original-17.obj" />
			</geometry>
		</visual>
		<visual name="vertical_side_panel-34">
			<origin xyz="0 0 0" />
			<geometry>
				<mesh filename="textured_objs/original-26.obj" />
			</geometry>
		</visual>
		<visual name="vertical_side_panel-35">
			<origin xyz="0 0 0" />
			<geometry>
				<mesh filename="textured_objs/original-16.obj" />
			</geometry>
		</visual>
		<visual name="vertical_side_panel-36">
			<origin xyz="0 0 0" />
			<geometry>
				<mesh filename="textured_objs/original-24.obj" />
			</geometry>
		</visual>
		<visual name="bar_stretcher-99">
			<origin xyz="0 0 0" />
			<geometry>
				<mesh filename="textured_objs/original-22.obj" />
			</geometry>
		</visual>
		<visual name="bar_stretcher-100">
			<origin xyz="0 0 0" />
			<geometry>
				<mesh filename="textured_objs/original-13.obj" />
			</geometry>
		</visual>
		<visual name="bar_stretcher-101">
			<origin xyz="0 0 0" />
			<geometry>
				<mesh filename="textured_objs/original-12.obj" />
			</geometry>
		</visual>
		<visual name="bar_stretcher-102">
			<origin xyz="0 0 0" />
			<geometry>
				<mesh filename="textured_objs/original-21.obj" />
			</geometry>
		</visual>
		<visual name="bar_stretcher-103">
			<origin xyz="0 0 0" />
			<geometry>
				<mesh filename="textured_objs/original-19.obj" />
			</geometry>
		</visual>
		<visual name="bar_stretcher-104">
			<origin xyz="0 0 0" />
			<geometry>
				<mesh filename="textured_objs/original-14.obj" />
			</geometry>
		</visual>
		<visual name="bar_stretcher-105">
			<origin xyz="0 0 0" />
			<geometry>
				<mesh filename="textured_objs/original-15.obj" />
			</geometry>
		</visual>
		<visual name="vertical_divider_panel-106">
			<origin xyz="0 0 0" />
			<geometry>
				<mesh filename="textured_objs/original-36.obj" />
			</geometry>
		</visual>
		<visual name="vertical_divider_panel-107">
			<origin xyz="0 0 0" />
			<geometry>
				<mesh filename="textured_objs/original-48.obj" />
			</geometry>
		</visual>
		<visual name="vertical_divider_panel-108">
			<origin xyz="0 0 0" />
			<geometry>
				<mesh filename="textured_objs/original-47.obj" />
			</geometry>
		</visual>
		<visual name="vertical_divider_panel-109">
			<origin xyz="0 0 0" />
			<geometry>
				<mesh filename="textured_objs/original-84.obj" />
			</geometry>
		</visual>
		<visual name="vertical_divider_panel-110">
			<origin xyz="0 0 0" />
			<geometry>
				<mesh filename="textured_objs/original-85.obj" />
			</geometry>
		</visual>
		<visual name="vertical_divider_panel-111">
			<origin xyz="0 0 0" />
			<geometry>
				<mesh filename="textured_objs/original-10.obj" />
			</geometry>
		</visual>
		<visual name="vertical_divider_panel-112">
			<origin xyz="0 0 0" />
			<geometry>
				<mesh filename="textured_objs/original-70.obj" />
			</geometry>
		</visual>
		<visual name="vertical_divider_panel-113">
			<origin xyz="0 0 0" />
			<geometry>
				<mesh filename="textured_objs/original-59.obj" />
			</geometry>
		</visual>
		<visual name="vertical_divider_panel-114">
			<origin xyz="0 0 0" />
			<geometry>
				<mesh filename="textured_objs/original-58.obj" />
			</geometry>
		</visual>
		<visual name="bar_stretcher-115">
			<origin xyz="0 0 0" />
			<geometry>
				<mesh filename="textured_objs/original-18.obj" />
			</geometry>
		</visual>
		<visual name="vertical_divider_panel-116">
			<origin xyz="0 0 0" />
			<geometry>
				<mesh filename="textured_objs/original-37.obj" />
			</geometry>
		</visual>
		<visual name="tabletop_connector-119">
			<origin xyz="0 0 0" />
			<geometry>
				<mesh filename="textured_objs/original-65.obj" />
			</geometry>
		</visual>
		<visual name="tabletop_connector-120">
			<origin xyz="0 0 0" />
			<geometry>
				<mesh filename="textured_objs/original-64.obj" />
			</geometry>
		</visual>
		<collision>
			<origin xyz="0 0 0" />
			<geometry>
				<mesh filename="textured_objs/original-1.obj" />
			</geometry>
		</collision>
		<collision>
			<origin xyz="0 0 0" />
			<geometry>
				<mesh filename="textured_objs/original-27.obj" />
			</geometry>
		</collision>
		<collision>
			<origin xyz="0 0 0" />
			<geometry>
				<mesh filename="textured_objs/original-29.obj" />
			</geometry>
		</collision>
		<collision>
			<origin xyz="0 0 0" />
			<geometry>
				<mesh filename="textured_objs/original-23.obj" />
			</geometry>
		</collision>
		<collision>
			<origin xyz="0 0 0" />
			<geometry>
				<mesh filename="textured_objs/original-20.obj" />
			</geometry>
		</collision>
		<collision>
			<origin xyz="0 0 0" />
			<geometry>
				<mesh filename="textured_objs/original-25.obj" />
			</geometry>
		</collision>
		<collision>
			<origin xyz="0 0 0" />
			<geometry>
				<mesh filename="textured_objs/original-30.obj" />
			</geometry>
		</collision>
		<collision>
			<origin xyz="0 0 0" />
			<geometry>
				<mesh filename="textured_objs/original-28.obj" />
			</geometry>
		</collision>
		<collision>
			<origin xyz="0 0 0" />
			<geometry>
				<mesh filename="textured_objs/original-17.obj" />
			</geometry>
		</collision>
		<collision>
			<origin xyz="0 0 0" />
			<geometry>
				<mesh filename="textured_objs/original-26.obj" />
			</geometry>
		</collision>
		<collision>
			<origin xyz="0 0 0" />
			<geometry>
				<mesh filename="textured_objs/original-16.obj" />
			</geometry>
		</collision>
		<collision>
			<origin xyz="0 0 0" />
			<geometry>
				<mesh filename="textured_objs/original-24.obj" />
			</geometry>
		</collision>
		<collision>
			<origin xyz="0 0 0" />
			<geometry>
				<mesh filename="textured_objs/original-22.obj" />
			</geometry>
		</collision>
		<collision>
			<origin xyz="0 0 0" />
			<geometry>
				<mesh filename="textured_objs/original-13.obj" />
			</geometry>
		</collision>
		<collision>
			<origin xyz="0 0 0" />
			<geometry>
				<mesh filename="textured_objs/original-12.obj" />
			</geometry>
		</collision>
		<collision>
			<origin xyz="0 0 0" />
			<geometry>
				<mesh filename="textured_objs/original-21.obj" />
			</geometry>
		</collision>
		<collision>
			<origin xyz="0 0 0" />
			<geometry>
				<mesh filename="textured_objs/original-19.obj" />
			</geometry>
		</collision>
		<collision>
			<origin xyz="0 0 0" />
			<geometry>
				<mesh filename="textured_objs/original-14.obj" />
			</geometry>
		</collision>
		<collision>
			<origin xyz="0 0 0" />
			<geometry>
				<mesh filename="textured_objs/original-15.obj" />
			</geometry>
		</collision>
		<collision>
			<origin xyz="0 0 0" />
			<geometry>
				<mesh filename="textured_objs/original-36.obj" />
			</geometry>
		</collision>
		<collision>
			<origin xyz="0 0 0" />
			<geometry>
				<mesh filename="textured_objs/original-48.obj" />
			</geometry>
		</collision>
		<collision>
			<origin xyz="0 0 0" />
			<geometry>
				<mesh filename="textured_objs/original-47.obj" />
			</geometry>
		</collision>
		<collision>
			<origin xyz="0 0 0" />
			<geometry>
				<mesh filename="textured_objs/original-84.obj" />
			</geometry>
		</collision>
		<collision>
			<origin xyz="0 0 0" />
			<geometry>
				<mesh filename="textured_objs/original-85.obj" />
			</geometry>
		</collision>
		<collision>
			<origin xyz="0 0 0" />
			<geometry>
				<mesh filename="textured_objs/original-10.obj" />
			</geometry>
		</collision>
		<collision>
			<origin xyz="0 0 0" />
			<geometry>
				<mesh filename="textured_objs/original-70.obj" />
			</geometry>
		</collision>
		<collision>
			<origin xyz="0 0 0" />
			<geometry>
				<mesh filename="textured_objs/original-59.obj" />
			</geometry>
		</collision>
		<collision>
			<origin xyz="0 0 0" />
			<geometry>
				<mesh filename="textured_objs/original-58.obj" />
			</geometry>
		</collision>
		<collision>
			<origin xyz="0 0 0" />
			<geometry>
				<mesh filename="textured_objs/original-18.obj" />
			</geometry>
		</collision>
		<collision>
			<origin xyz="0 0 0" />
			<geometry>
				<mesh filename="textured_objs/original-37.obj" />
			</geometry>
		</collision>
		<collision>
			<origin xyz="0 0 0" />
			<geometry>
				<mesh filename="textured_objs/original-65.obj" />
			</geometry>
		</collision>
		<collision>
			<origin xyz="0 0 0" />
			<geometry>
				<mesh filename="textured_objs/original-64.obj" />
			</geometry>
		</collision>
	</link>
	<joint name="joint_6" type="fixed">
		<origin rpy="1.570796326794897 0 -1.570796326794897" xyz="0 0 0" />
		<child link="link_6" />
		<parent link="base" />
	</joint>
</robot>