<?xml version='1.0' encoding='utf-8'?>
<robot name="partnet_56ea26c10c478555a31cc7b61ec6561">
	<link name="base" />
	<link name="link_0">
		<visual name="drawer_front-43">
			<origin xyz="0 0 0" />
			<geometry>
				<mesh filename="textured_objs/original-33.obj" />
			</geometry>
		</visual>
		<visual name="drawer_front-43">
			<origin xyz="0 0 0" />
			<geometry>
				<mesh filename="textured_objs/original-35.obj" />
			</geometry>
		</visual>
		<visual name="drawer_side-44">
			<origin xyz="0 0 0" />
			<geometry>
				<mesh filename="textured_objs/original-38.obj" />
			</geometry>
		</visual>
		<visual name="drawer_side-45">
			<origin xyz="0 0 0" />
			<geometry>
				<mesh filename="textured_objs/original-36.obj" />
			</geometry>
		</visual>
		<visual name="drawer_back-46">
			<origin xyz="0 0 0" />
			<geometry>
				<mesh filename="textured_objs/original-34.obj" />
			</geometry>
		</visual>
		<visual name="drawer_bottom-47">
			<origin xyz="0 0 0" />
			<geometry>
				<mesh filename="textured_objs/original-37.obj" />
			</geometry>
		</visual>
		<visual name="handle-42">
			<origin xyz="0 0 0" />
			<geometry>
				<mesh filename="textured_objs/original-31.obj" />
			</geometry>
		</visual>
		<collision>
			<origin xyz="0 0 0" />
			<geometry>
				<mesh filename="textured_objs/original-33.obj" />
			</geometry>
		</collision>
		<collision>
			<origin xyz="0 0 0" />
			<geometry>
				<mesh filename="textured_objs/original-35.obj" />
			</geometry>
		</collision>
		<collision>
			<origin xyz="0 0 0" />
			<geometry>
				<mesh filename="textured_objs/original-38.obj" />
			</geometry>
		</collision>
		<collision>
			<origin xyz="0 0 0" />
			<geometry>
				<mesh filename="textured_objs/original-36.obj" />
			</geometry>
		</collision>
		<collision>
			<origin xyz="0 0 0" />
			<geometry>
				<mesh filename="textured_objs/original-34.obj" />
			</geometry>
		</collision>
		<collision>
			<origin xyz="0 0 0" />
			<geometry>
				<mesh filename="textured_objs/original-37.obj" />
			</geometry>
		</collision>
		<collision>
			<origin xyz="0 0 0" />
			<geometry>
				<mesh filename="textured_objs/original-31.obj" />
			</geometry>
		</collision>
	</link>
	<joint name="joint_0" type="prismatic">
		<origin xyz="0 0 0" />
		<axis xyz="0 0 1" />
		<child link="link_0" />
		<parent link="link_3" />
		<limit lower="0" upper="0.4039999999999999" />
	</joint>
	<link name="link_1">
		<visual name="drawer_front-36">
			<origin xyz="0 0 0" />
			<geometry>
				<mesh filename="textured_objs/original-24.obj" />
			</geometry>
		</visual>
		<visual name="drawer_front-36">
			<origin xyz="0 0 0" />
			<geometry>
				<mesh filename="textured_objs/original-26.obj" />
			</geometry>
		</visual>
		<visual name="drawer_side-37">
			<origin xyz="0 0 0" />
			<geometry>
				<mesh filename="textured_objs/original-29.obj" />
			</geometry>
		</visual>
		<visual name="drawer_side-38">
			<origin xyz="0 0 0" />
			<geometry>
				<mesh filename="textured_objs/original-27.obj" />
			</geometry>
		</visual>
		<visual name="drawer_back-39">
			<origin xyz="0 0 0" />
			<geometry>
				<mesh filename="textured_objs/original-25.obj" />
			</geometry>
		</visual>
		<visual name="drawer_bottom-40">
			<origin xyz="0 0 0" />
			<geometry>
				<mesh filename="textured_objs/original-28.obj" />
			</geometry>
		</visual>
		<visual name="handle-35">
			<origin xyz="0 0 0" />
			<geometry>
				<mesh filename="textured_objs/original-22.obj" />
			</geometry>
		</visual>
		<collision>
			<origin xyz="0 0 0" />
			<geometry>
				<mesh filename="textured_objs/original-24.obj" />
			</geometry>
		</collision>
		<collision>
			<origin xyz="0 0 0" />
			<geometry>
				<mesh filename="textured_objs/original-26.obj" />
			</geometry>
		</collision>
		<collision>
			<origin xyz="0 0 0" />
			<geometry>
				<mesh filename="textured_objs/original-29.obj" />
			</geometry>
		</collision>
		<collision>
			<origin xyz="0 0 0" />
			<geometry>
				<mesh filename="textured_objs/original-27.obj" />
			</geometry>
		</collision>
		<collision>
			<origin xyz="0 0 0" />
			<geometry>
				<mesh filename="textured_objs/original-25.obj" />
			</geometry>
		</collision>
		<collision>
			<origin xyz="0 0 0" />
			<geometry>
				<mesh filename="textured_objs/original-28.obj" />
			</geometry>
		</collision>
		<collision>
			<origin xyz="0 0 0" />
			<geometry>
				<mesh filename="textured_objs/original-22.obj" />
			</geometry>
		</collision>
	</link>
	<joint name="joint_1" type="prismatic">
		<origin xyz="0 0 0" />
		<axis xyz="0 0 1" />
		<child link="link_1" />
		<parent link="link_3" />
		<limit lower="0" upper="0.42399999999999993" />
	</joint>
	<link name="link_2">
		<visual name="drawer_front-29">
			<origin xyz="0 0 0" />
			<geometry>
				<mesh filename="textured_objs/original-3.obj" />
			</geometry>
		</visual>
		<visual name="drawer_front-29">
			<origin xyz="0 0 0" />
			<geometry>
				<mesh filename="textured_objs/original-5.obj" />
			</geometry>
		</visual>
		<visual name="drawer_side-30">
			<origin xyz="0 0 0" />
			<geometry>
				<mesh filename="textured_objs/original-8.obj" />
			</geometry>
		</visual>
		<visual name="drawer_side-31">
			<origin xyz="0 0 0" />
			<geometry>
				<mesh filename="textured_objs/original-6.obj" />
			</geometry>
		</visual>
		<visual name="drawer_back-32">
			<origin xyz="0 0 0" />
			<geometry>
				<mesh filename="textured_objs/original-4.obj" />
			</geometry>
		</visual>
		<visual name="drawer_bottom-33">
			<origin xyz="0 0 0" />
			<geometry>
				<mesh filename="textured_objs/original-7.obj" />
			</geometry>
		</visual>
		<visual name="handle-28">
			<origin xyz="0 0 0" />
			<geometry>
				<mesh filename="textured_objs/original-9.obj" />
			</geometry>
		</visual>
		<collision>
			<origin xyz="0 0 0" />
			<geometry>
				<mesh filename="textured_objs/original-3.obj" />
			</geometry>
		</collision>
		<collision>
			<origin xyz="0 0 0" />
			<geometry>
				<mesh filename="textured_objs/original-5.obj" />
			</geometry>
		</collision>
		<collision>
			<origin xyz="0 0 0" />
			<geometry>
				<mesh filename="textured_objs/original-8.obj" />
			</geometry>
		</collision>
		<collision>
			<origin xyz="0 0 0" />
			<geometry>
				<mesh filename="textured_objs/original-6.obj" />
			</geometry>
		</collision>
		<collision>
			<origin xyz="0 0 0" />
			<geometry>
				<mesh filename="textured_objs/original-4.obj" />
			</geometry>
		</collision>
		<collision>
			<origin xyz="0 0 0" />
			<geometry>
				<mesh filename="textured_objs/original-7.obj" />
			</geometry>
		</collision>
		<collision>
			<origin xyz="0 0 0" />
			<geometry>
				<mesh filename="textured_objs/original-9.obj" />
			</geometry>
		</collision>
	</link>
	<joint name="joint_2" type="prismatic">
		<origin xyz="0 0 0" />
		<axis xyz="0 0 1" />
		<child link="link_2" />
		<parent link="link_3" />
		<limit lower="0" upper="0.42399999999999993" />
	</joint>
	<link name="link_3">
		<visual name="board-49">
			<origin xyz="0 0 0" />
			<geometry>
				<mesh filename="textured_objs/original-11.obj" />
			</geometry>
		</visual>
		<visual name="shelf-8">
			<origin xyz="0 0 0" />
			<geometry>
				<mesh filename="textured_objs/original-18.obj" />
			</geometry>
		</visual>
		<visual name="back_panel-9">
			<origin xyz="0 0 0" />
			<geometry>
				<mesh filename="textured_objs/original-13.obj" />
			</geometry>
		</visual>
		<visual name="vertical_side_panel-10">
			<origin xyz="0 0 0" />
			<geometry>
				<mesh filename="textured_objs/original-15.obj" />
			</geometry>
		</visual>
		<visual name="vertical_side_panel-11">
			<origin xyz="0 0 0" />
			<geometry>
				<mesh filename="textured_objs/original-17.obj" />
			</geometry>
		</visual>
		<visual name="vertical_side_panel-12">
			<origin xyz="0 0 0" />
			<geometry>
				<mesh filename="textured_objs/original-20.obj" />
			</geometry>
		</visual>
		<visual name="bottom_panel-13">
			<origin xyz="0 0 0" />
			<geometry>
				<mesh filename="textured_objs/original-19.obj" />
			</geometry>
		</visual>
		<visual name="leg-14">
			<origin xyz="0 0 0" />
			<geometry>
				<mesh filename="textured_objs/new-7.obj" />
			</geometry>
		</visual>
		<visual name="leg-15">
			<origin xyz="0 0 0" />
			<geometry>
				<mesh filename="textured_objs/new-8.obj" />
			</geometry>
		</visual>
		<visual name="foot-16">
			<origin xyz="0 0 0" />
			<geometry>
				<mesh filename="textured_objs/new-1.obj" />
			</geometry>
		</visual>
		<visual name="foot-17">
			<origin xyz="0 0 0" />
			<geometry>
				<mesh filename="textured_objs/new-0.obj" />
			</geometry>
		</visual>
		<visual name="foot-18">
			<origin xyz="0 0 0" />
			<geometry>
				<mesh filename="textured_objs/new-5.obj" />
			</geometry>
		</visual>
		<visual name="foot-19">
			<origin xyz="0 0 0" />
			<geometry>
				<mesh filename="textured_objs/new-4.obj" />
			</geometry>
		</visual>
		<visual name="runner-20">
			<origin xyz="0 0 0" />
			<geometry>
				<mesh filename="textured_objs/new-6.obj" />
			</geometry>
		</visual>
		<visual name="runner-21">
			<origin xyz="0 0 0" />
			<geometry>
				<mesh filename="textured_objs/new-2.obj" />
			</geometry>
		</visual>
		<visual name="bar_stretcher-22">
			<origin xyz="0 0 0" />
			<geometry>
				<mesh filename="textured_objs/new-3.obj" />
			</geometry>
		</visual>
		<visual name="tabletop_connector-23">
			<origin xyz="0 0 0" />
			<geometry>
				<mesh filename="textured_objs/new-10.obj" />
			</geometry>
		</visual>
		<visual name="tabletop_connector-24">
			<origin xyz="0 0 0" />
			<geometry>
				<mesh filename="textured_objs/new-11.obj" />
			</geometry>
		</visual>
		<visual name="tabletop_connector-25">
			<origin xyz="0 0 0" />
			<geometry>
				<mesh filename="textured_objs/new-12.obj" />
			</geometry>
		</visual>
		<visual name="tabletop_connector-26">
			<origin xyz="0 0 0" />
			<geometry>
				<mesh filename="textured_objs/new-9.obj" />
			</geometry>
		</visual>
		<collision>
			<origin xyz="0 0 0" />
			<geometry>
				<mesh filename="textured_objs/original-11.obj" />
			</geometry>
		</collision>
		<collision>
			<origin xyz="0 0 0" />
			<geometry>
				<mesh filename="textured_objs/original-18.obj" />
			</geometry>
		</collision>
		<collision>
			<origin xyz="0 0 0" />
			<geometry>
				<mesh filename="textured_objs/original-13.obj" />
			</geometry>
		</collision>
		<collision>
			<origin xyz="0 0 0" />
			<geometry>
				<mesh filename="textured_objs/original-15.obj" />
			</geometry>
		</collision>
		<collision>
			<origin xyz="0 0 0" />
			<geometry>
				<mesh filename="textured_objs/original-17.obj" />
			</geometry>
		</collision>
		<collision>
			<origin xyz="0 0 0" />
			<geometry>
				<mesh filename="textured_objs/original-20.obj" />
			</geometry>
		</collision>
		<collision>
			<origin xyz="0 0 0" />
			<geometry>
				<mesh filename="textured_objs/original-19.obj" />
			</geometry>
		</collision>
		<collision>
			<origin xyz="0 0 0" />
			<geometry>
				<mesh filename="textured_objs/new-7.obj" />
			</geometry>
		</collision>
		<collision>
			<origin xyz="0 0 0" />
			<geometry>
				<mesh filename="textured_objs/new-8.obj" />
			</geometry>
		</collision>
		<collision>
			<origin xyz="0 0 0" />
			<geometry>
				<mesh filename="textured_objs/new-1.obj" />
			</geometry>
		</collision>
		<collision>
			<origin xyz="0 0 0" />
			<geometry>
				<mesh filename="textured_objs/new-0.obj" />
			</geometry>
		</collision>
		<collision>
			<origin xyz="0 0 0" />
			<geometry>
				<mesh filename="textured_objs/new-5.obj" />
			</geometry>
		</collision>
		<collision>
			<origin xyz="0 0 0" />
			<geometry>
				<mesh filename="textured_objs/new-4.obj" />
			</geometry>
		</collision>
		<collision>
			<origin xyz="0 0 0" />
			<geometry>
				<mesh filename="textured_objs/new-6.obj" />
			</geometry>
		</collision>
		<collision>
			<origin xyz="0 0 0" />
			<geometry>
				<mesh filename="textured_objs/new-2.obj" />
			</geometry>
		</collision>
		<collision>
			<origin xyz="0 0 0" />
			<geometry>
				<mesh filename="textured_objs/new-3.obj" />
			</geometry>
		</collision>
		<collision>
			<origin xyz="0 0 0" />
			<geometry>
				<mesh filename="textured_objs/new-10.obj" />
			</geometry>
		</collision>
		<collision>
			<origin xyz="0 0 0" />
			<geometry>
				<mesh filename="textured_objs/new-11.obj" />
			</geometry>
		</collision>
		<collision>
			<origin xyz="0 0 0" />
			<geometry>
				<mesh filename="textured_objs/new-12.obj" />
			</geometry>
		</collision>
		<collision>
			<origin xyz="0 0 0" />
			<geometry>
				<mesh filename="textured_objs/new-9.obj" />
			</geometry>
		</collision>
	</link>
	<joint name="joint_3" type="fixed">
		<origin rpy="1.570796326794897 0 -1.570796326794897" xyz="0 0 0" />
		<child link="link_3" />
		<parent link="base" />
	</joint>
</robot>