<?xml version='1.0' encoding='utf-8'?>
<robot name="partnet_c7778ca8dabfc6809856fa70a578baeb">
	<link name="base" />
	<link name="link_0">
		<visual name="wheel-141">
			<origin xyz="0 0.20046622767157418 0.5157304023035693" />
			<geometry>
				<mesh filename="textured_objs/original-4.obj" />
			</geometry>
		</visual>
		<collision>
			<origin xyz="0 0.20046622767157418 0.5157304023035693" />
			<geometry>
				<mesh filename="textured_objs/original-4.obj" />
			</geometry>
		</collision>
	</link>
	<joint name="joint_0" type="continuous">
		<origin xyz="0 -0.20046622767157418 -0.5157304023035693" />
		<axis xyz="-1 0 0" />
		<child link="link_0" />
		<parent link="link_4" />
	</joint>
	<link name="link_1">
		<visual name="wheel-132">
			<origin xyz="0 0.2004662276711634 0.5062325976966009" />
			<geometry>
				<mesh filename="textured_objs/original-40.obj" />
			</geometry>
		</visual>
		<collision>
			<origin xyz="0 0.2004662276711634 0.5062325976966009" />
			<geometry>
				<mesh filename="textured_objs/original-40.obj" />
			</geometry>
		</collision>
	</link>
	<joint name="joint_1" type="continuous">
		<origin xyz="0 -0.2004662276711634 -0.5062325976966009" />
		<axis xyz="-1 0 0" />
		<child link="link_1" />
		<parent link="link_4" />
	</joint>
	<link name="link_2">
		<visual name="wheel-150">
			<origin xyz="0 0.2004662276711634 -0.6454735976966008" />
			<geometry>
				<mesh filename="textured_objs/original-28.obj" />
			</geometry>
		</visual>
		<collision>
			<origin xyz="0 0.2004662276711634 -0.6454735976966008" />
			<geometry>
				<mesh filename="textured_objs/original-28.obj" />
			</geometry>
		</collision>
	</link>
	<joint name="joint_2" type="continuous">
		<origin xyz="0 -0.2004662276711634 0.6454735976966008" />
		<axis xyz="-1 0 0" />
		<child link="link_2" />
		<parent link="link_4" />
	</joint>
	<link name="link_3">
		<visual name="wheel-112">
			<origin xyz="0 0.2004662276711634 -0.6375644023033991" />
			<geometry>
				<mesh filename="textured_objs/original-16.obj" />
			</geometry>
		</visual>
		<collision>
			<origin xyz="0 0.2004662276711634 -0.6375644023033991" />
			<geometry>
				<mesh filename="textured_objs/original-16.obj" />
			</geometry>
		</collision>
	</link>
	<joint name="joint_3" type="continuous">
		<origin xyz="0 -0.2004662276711634 0.6375644023033991" />
		<axis xyz="-1 0 0" />
		<child link="link_3" />
		<parent link="link_4" />
	</joint>
	<link name="link_4">
		<visual name="board-102">
			<origin xyz="0 0 0" />
			<geometry>
				<mesh filename="textured_objs/original-34.obj" />
			</geometry>
		</visual>
		<visual name="board-102">
			<origin xyz="0 0 0" />
			<geometry>
				<mesh filename="textured_objs/original-33.obj" />
			</geometry>
		</visual>
		<visual name="board-102">
			<origin xyz="0 0 0" />
			<geometry>
				<mesh filename="textured_objs/original-36.obj" />
			</geometry>
		</visual>
		<visual name="board-102">
			<origin xyz="0 0 0" />
			<geometry>
				<mesh filename="textured_objs/original-35.obj" />
			</geometry>
		</visual>
		<visual name="board-102">
			<origin xyz="0 0 0" />
			<geometry>
				<mesh filename="textured_objs/original-45.obj" />
			</geometry>
		</visual>
		<visual name="board-102">
			<origin xyz="0 0 0" />
			<geometry>
				<mesh filename="textured_objs/original-21.obj" />
			</geometry>
		</visual>
		<visual name="board-102">
			<origin xyz="0 0 0" />
			<geometry>
				<mesh filename="textured_objs/original-24.obj" />
			</geometry>
		</visual>
		<visual name="board-102">
			<origin xyz="0 0 0" />
			<geometry>
				<mesh filename="textured_objs/original-23.obj" />
			</geometry>
		</visual>
		<visual name="board-102">
			<origin xyz="0 0 0" />
			<geometry>
				<mesh filename="textured_objs/original-22.obj" />
			</geometry>
		</visual>
		<visual name="board-102">
			<origin xyz="0 0 0" />
			<geometry>
				<mesh filename="textured_objs/original-10.obj" />
			</geometry>
		</visual>
		<visual name="board-102">
			<origin xyz="0 0 0" />
			<geometry>
				<mesh filename="textured_objs/original-12.obj" />
			</geometry>
		</visual>
		<visual name="board-102">
			<origin xyz="0 0 0" />
			<geometry>
				<mesh filename="textured_objs/original-11.obj" />
			</geometry>
		</visual>
		<visual name="board-102">
			<origin xyz="0 0 0" />
			<geometry>
				<mesh filename="textured_objs/original-46.obj" />
			</geometry>
		</visual>
		<visual name="board-102">
			<origin xyz="0 0 0" />
			<geometry>
				<mesh filename="textured_objs/original-47.obj" />
			</geometry>
		</visual>
		<visual name="board-102">
			<origin xyz="0 0 0" />
			<geometry>
				<mesh filename="textured_objs/original-48.obj" />
			</geometry>
		</visual>
		<visual name="board-102">
			<origin xyz="0 0 0" />
			<geometry>
				<mesh filename="textured_objs/original-49.obj" />
			</geometry>
		</visual>
		<visual name="caster_stem-140">
			<origin xyz="0 0 0" />
			<geometry>
				<mesh filename="textured_objs/original-8.obj" />
			</geometry>
		</visual>
		<visual name="brake-142">
			<origin xyz="0 0 0" />
			<geometry>
				<mesh filename="textured_objs/original-7.obj" />
			</geometry>
		</visual>
		<visual name="caster_stem-131">
			<origin xyz="0 0 0" />
			<geometry>
				<mesh filename="textured_objs/original-44.obj" />
			</geometry>
		</visual>
		<visual name="brake-133">
			<origin xyz="0 0 0" />
			<geometry>
				<mesh filename="textured_objs/original-43.obj" />
			</geometry>
		</visual>
		<visual name="caster_stem-149">
			<origin xyz="0 0 0" />
			<geometry>
				<mesh filename="textured_objs/original-32.obj" />
			</geometry>
		</visual>
		<visual name="brake-151">
			<origin xyz="0 0 0" />
			<geometry>
				<mesh filename="textured_objs/original-31.obj" />
			</geometry>
		</visual>
		<visual name="caster_stem-111">
			<origin xyz="0 0 0" />
			<geometry>
				<mesh filename="textured_objs/original-20.obj" />
			</geometry>
		</visual>
		<visual name="brake-113">
			<origin xyz="0 0 0" />
			<geometry>
				<mesh filename="textured_objs/original-19.obj" />
			</geometry>
		</visual>
		<visual name="other_leaf-147">
			<origin xyz="0 0 0" />
			<geometry>
				<mesh filename="textured_objs/original-3.obj" />
			</geometry>
		</visual>
		<visual name="other_leaf-148">
			<origin xyz="0 0 0" />
			<geometry>
				<mesh filename="textured_objs/original-2.obj" />
			</geometry>
		</visual>
		<visual name="other_leaf-145">
			<origin xyz="0 0 0" />
			<geometry>
				<mesh filename="textured_objs/original-6.obj" />
			</geometry>
		</visual>
		<visual name="other_leaf-146">
			<origin xyz="0 0 0" />
			<geometry>
				<mesh filename="textured_objs/original-5.obj" />
			</geometry>
		</visual>
		<visual name="other_leaf-138">
			<origin xyz="0 0 0" />
			<geometry>
				<mesh filename="textured_objs/original-38.obj" />
			</geometry>
		</visual>
		<visual name="other_leaf-139">
			<origin xyz="0 0 0" />
			<geometry>
				<mesh filename="textured_objs/original-39.obj" />
			</geometry>
		</visual>
		<visual name="other_leaf-136">
			<origin xyz="0 0 0" />
			<geometry>
				<mesh filename="textured_objs/original-42.obj" />
			</geometry>
		</visual>
		<visual name="other_leaf-137">
			<origin xyz="0 0 0" />
			<geometry>
				<mesh filename="textured_objs/original-41.obj" />
			</geometry>
		</visual>
		<visual name="other_leaf-156">
			<origin xyz="0 0 0" />
			<geometry>
				<mesh filename="textured_objs/original-26.obj" />
			</geometry>
		</visual>
		<visual name="other_leaf-157">
			<origin xyz="0 0 0" />
			<geometry>
				<mesh filename="textured_objs/original-27.obj" />
			</geometry>
		</visual>
		<visual name="other_leaf-154">
			<origin xyz="0 0 0" />
			<geometry>
				<mesh filename="textured_objs/original-29.obj" />
			</geometry>
		</visual>
		<visual name="other_leaf-155">
			<origin xyz="0 0 0" />
			<geometry>
				<mesh filename="textured_objs/original-30.obj" />
			</geometry>
		</visual>
		<visual name="other_leaf-118">
			<origin xyz="0 0 0" />
			<geometry>
				<mesh filename="textured_objs/original-15.obj" />
			</geometry>
		</visual>
		<visual name="other_leaf-119">
			<origin xyz="0 0 0" />
			<geometry>
				<mesh filename="textured_objs/original-14.obj" />
			</geometry>
		</visual>
		<visual name="other_leaf-116">
			<origin xyz="0 0 0" />
			<geometry>
				<mesh filename="textured_objs/original-18.obj" />
			</geometry>
		</visual>
		<visual name="other_leaf-117">
			<origin xyz="0 0 0" />
			<geometry>
				<mesh filename="textured_objs/original-17.obj" />
			</geometry>
		</visual>
		<collision>
			<origin xyz="0 0 0" />
			<geometry>
				<mesh filename="textured_objs/original-34.obj" />
			</geometry>
		</collision>
		<collision>
			<origin xyz="0 0 0" />
			<geometry>
				<mesh filename="textured_objs/original-33.obj" />
			</geometry>
		</collision>
		<collision>
			<origin xyz="0 0 0" />
			<geometry>
				<mesh filename="textured_objs/original-36.obj" />
			</geometry>
		</collision>
		<collision>
			<origin xyz="0 0 0" />
			<geometry>
				<mesh filename="textured_objs/original-35.obj" />
			</geometry>
		</collision>
		<collision>
			<origin xyz="0 0 0" />
			<geometry>
				<mesh filename="textured_objs/original-45.obj" />
			</geometry>
		</collision>
		<collision>
			<origin xyz="0 0 0" />
			<geometry>
				<mesh filename="textured_objs/original-21.obj" />
			</geometry>
		</collision>
		<collision>
			<origin xyz="0 0 0" />
			<geometry>
				<mesh filename="textured_objs/original-24.obj" />
			</geometry>
		</collision>
		<collision>
			<origin xyz="0 0 0" />
			<geometry>
				<mesh filename="textured_objs/original-23.obj" />
			</geometry>
		</collision>
		<collision>
			<origin xyz="0 0 0" />
			<geometry>
				<mesh filename="textured_objs/original-22.obj" />
			</geometry>
		</collision>
		<collision>
			<origin xyz="0 0 0" />
			<geometry>
				<mesh filename="textured_objs/original-10.obj" />
			</geometry>
		</collision>
		<collision>
			<origin xyz="0 0 0" />
			<geometry>
				<mesh filename="textured_objs/original-12.obj" />
			</geometry>
		</collision>
		<collision>
			<origin xyz="0 0 0" />
			<geometry>
				<mesh filename="textured_objs/original-11.obj" />
			</geometry>
		</collision>
		<collision>
			<origin xyz="0 0 0" />
			<geometry>
				<mesh filename="textured_objs/original-46.obj" />
			</geometry>
		</collision>
		<collision>
			<origin xyz="0 0 0" />
			<geometry>
				<mesh filename="textured_objs/original-47.obj" />
			</geometry>
		</collision>
		<collision>
			<origin xyz="0 0 0" />
			<geometry>
				<mesh filename="textured_objs/original-48.obj" />
			</geometry>
		</collision>
		<collision>
			<origin xyz="0 0 0" />
			<geometry>
				<mesh filename="textured_objs/original-49.obj" />
			</geometry>
		</collision>
		<collision>
			<origin xyz="0 0 0" />
			<geometry>
				<mesh filename="textured_objs/original-8.obj" />
			</geometry>
		</collision>
		<collision>
			<origin xyz="0 0 0" />
			<geometry>
				<mesh filename="textured_objs/original-7.obj" />
			</geometry>
		</collision>
		<collision>
			<origin xyz="0 0 0" />
			<geometry>
				<mesh filename="textured_objs/original-44.obj" />
			</geometry>
		</collision>
		<collision>
			<origin xyz="0 0 0" />
			<geometry>
				<mesh filename="textured_objs/original-43.obj" />
			</geometry>
		</collision>
		<collision>
			<origin xyz="0 0 0" />
			<geometry>
				<mesh filename="textured_objs/original-32.obj" />
			</geometry>
		</collision>
		<collision>
			<origin xyz="0 0 0" />
			<geometry>
				<mesh filename="textured_objs/original-31.obj" />
			</geometry>
		</collision>
		<collision>
			<origin xyz="0 0 0" />
			<geometry>
				<mesh filename="textured_objs/original-20.obj" />
			</geometry>
		</collision>
		<collision>
			<origin xyz="0 0 0" />
			<geometry>
				<mesh filename="textured_objs/original-19.obj" />
			</geometry>
		</collision>
		<collision>
			<origin xyz="0 0 0" />
			<geometry>
				<mesh filename="textured_objs/original-3.obj" />
			</geometry>
		</collision>
		<collision>
			<origin xyz="0 0 0" />
			<geometry>
				<mesh filename="textured_objs/original-2.obj" />
			</geometry>
		</collision>
		<collision>
			<origin xyz="0 0 0" />
			<geometry>
				<mesh filename="textured_objs/original-6.obj" />
			</geometry>
		</collision>
		<collision>
			<origin xyz="0 0 0" />
			<geometry>
				<mesh filename="textured_objs/original-5.obj" />
			</geometry>
		</collision>
		<collision>
			<origin xyz="0 0 0" />
			<geometry>
				<mesh filename="textured_objs/original-38.obj" />
			</geometry>
		</collision>
		<collision>
			<origin xyz="0 0 0" />
			<geometry>
				<mesh filename="textured_objs/original-39.obj" />
			</geometry>
		</collision>
		<collision>
			<origin xyz="0 0 0" />
			<geometry>
				<mesh filename="textured_objs/original-42.obj" />
			</geometry>
		</collision>
		<collision>
			<origin xyz="0 0 0" />
			<geometry>
				<mesh filename="textured_objs/original-41.obj" />
			</geometry>
		</collision>
		<collision>
			<origin xyz="0 0 0" />
			<geometry>
				<mesh filename="textured_objs/original-26.obj" />
			</geometry>
		</collision>
		<collision>
			<origin xyz="0 0 0" />
			<geometry>
				<mesh filename="textured_objs/original-27.obj" />
			</geometry>
		</collision>
		<collision>
			<origin xyz="0 0 0" />
			<geometry>
				<mesh filename="textured_objs/original-29.obj" />
			</geometry>
		</collision>
		<collision>
			<origin xyz="0 0 0" />
			<geometry>
				<mesh filename="textured_objs/original-30.obj" />
			</geometry>
		</collision>
		<collision>
			<origin xyz="0 0 0" />
			<geometry>
				<mesh filename="textured_objs/original-15.obj" />
			</geometry>
		</collision>
		<collision>
			<origin xyz="0 0 0" />
			<geometry>
				<mesh filename="textured_objs/original-14.obj" />
			</geometry>
		</collision>
		<collision>
			<origin xyz="0 0 0" />
			<geometry>
				<mesh filename="textured_objs/original-18.obj" />
			</geometry>
		</collision>
		<collision>
			<origin xyz="0 0 0" />
			<geometry>
				<mesh filename="textured_objs/original-17.obj" />
			</geometry>
		</collision>
	</link>
	<joint name="joint_4" type="fixed">
		<origin rpy="1.570796326794897 0 -1.570796326794897" xyz="0 0 0" />
		<child link="link_4" />
		<parent link="base" />
	</joint>
</robot>