<?xml version="1.0"?>
<robot name="hand">
  <material name="blue">
    <color rgba="0 0 0.8 1"/>
  </material>

  <material name="white">
    <color rgba="1 1 1 1"/>
  </material>

  <material name="red">
    <color rgba="0.8 0 0 1"/>
  </material>

  <material name="green">
    <color rgba="0 0.8 0 1"/>
  </material>

  <link name="base_link">
    <visual>
      <geometry>
        <cylinder length="0.02" radius="0.02"/>
      </geometry>
      <origin rpy="0 0 0" xyz="0 0 0.01"/>
    </visual>
    <collision>
      <geometry>
        <cylinder length="0.02" radius="0.02"/>
      </geometry>
      <origin rpy="0 0 0" xyz="0 0 0.02"/>
    </collision>
  </link>

  <link name="finger_1">
    <visual>
      <geometry>
        <mesh filename="meshes/visual/simplified_finger_mesh.stl"/>
      </geometry>
      <origin rpy="0 0 0" xyz="0 0 0"/>
      <material name="red"/>
    </visual>
    <collision>
      <geometry>
	 	    <mesh filename="meshes/collision/simplified_finger_mesh.stl"/>
      </geometry>
      <origin rpy="0 0 0" xyz="0 0 0"/>
    </collision>
  </link>

  <link name="finger_2">
    <visual>
      <geometry>
        <mesh filename="meshes/visual/simplified_finger_mesh.stl"/>
      </geometry>
      <origin rpy="0 0 0" xyz="0 0 0"/>
      <material name="green"/>
    </visual>
    <collision>
      <geometry>
	 	    <mesh filename="meshes/collision/simplified_finger_mesh.stl"/>
      </geometry>
      <origin rpy="0 0 0" xyz="0 0 0"/>
    </collision>
  </link>

  <joint name="base_to_finger_1" type="revolute">
    <parent link="base_link"/>
    <child link="finger_1"/>
    <origin rpy="0 -0.7854 3.14159" xyz="0.02 0 0.04"/>
    <limit effort="1000.0" lower="0" upper="0.7854" velocity="0.5"/>
    <axis xyz="0 1 0"/>
  </joint>

  <joint name="base_to_finger_2" type="revolute">
    <parent link="base_link"/>
    <child link="finger_2"/>
    <origin rpy="0 -0.7854 0" xyz="-0.02 0 0.04"/>
    <limit effort="1000.0" lower="0" upper="0.7854" velocity="0.5"/>
    <axis xyz="0 1 0"/>
  </joint>

</robot>