<?xml version='1.0' encoding='utf-8'?>
<robot name="partnet_53e1d0645ff2afc54c3aee8e9d3a6ffa">
	<link name="base" />
	<link name="link_0">
		<visual name="vertical_side_panel-62">
			<origin xyz="0 0 0" />
			<geometry>
				<mesh filename="textured_objs/original-7.obj" />
			</geometry>
		</visual>
		<visual name="vertical_side_panel-62">
			<origin xyz="0 0 0" />
			<geometry>
				<mesh filename="textured_objs/original-6.obj" />
			</geometry>
		</visual>
		<visual name="vertical_side_panel-63">
			<origin xyz="0 0 0" />
			<geometry>
				<mesh filename="textured_objs/original-4.obj" />
			</geometry>
		</visual>
		<visual name="vertical_side_panel-63">
			<origin xyz="0 0 0" />
			<geometry>
				<mesh filename="textured_objs/original-3.obj" />
			</geometry>
		</visual>
		<visual name="back_panel-64">
			<origin xyz="0 0 0" />
			<geometry>
				<mesh filename="textured_objs/original-15.obj" />
			</geometry>
		</visual>
		<visual name="bottom_panel-65">
			<origin xyz="0 0 0" />
			<geometry>
				<mesh filename="textured_objs/original-10.obj" />
			</geometry>
		</visual>
		<visual name="bottom_panel-65">
			<origin xyz="0 0 0" />
			<geometry>
				<mesh filename="textured_objs/original-9.obj" />
			</geometry>
		</visual>
		<visual name="top_panel-66">
			<origin xyz="0 0 0" />
			<geometry>
				<mesh filename="textured_objs/original-12.obj" />
			</geometry>
		</visual>
		<visual name="top_panel-66">
			<origin xyz="0 0 0" />
			<geometry>
				<mesh filename="textured_objs/original-13.obj" />
			</geometry>
		</visual>
		<visual name="frame_horizontal_bar-67">
			<origin xyz="0 0 0" />
			<geometry>
				<mesh filename="textured_objs/original-16.obj" />
			</geometry>
		</visual>
		<visual name="frame_horizontal_bar-68">
			<origin xyz="0 0 0" />
			<geometry>
				<mesh filename="textured_objs/original-14.obj" />
			</geometry>
		</visual>
		<visual name="drawer_slider-47">
			<origin xyz="0 0 0" />
			<geometry>
				<mesh filename="textured_objs/original-43.obj" />
			</geometry>
		</visual>
		<visual name="drawer_slider-48">
			<origin xyz="0 0 0" />
			<geometry>
				<mesh filename="textured_objs/original-44.obj" />
			</geometry>
		</visual>
		<visual name="drawer_slider-38">
			<origin xyz="0 0 0" />
			<geometry>
				<mesh filename="textured_objs/original-27.obj" />
			</geometry>
		</visual>
		<visual name="drawer_slider-39">
			<origin xyz="0 0 0" />
			<geometry>
				<mesh filename="textured_objs/original-28.obj" />
			</geometry>
		</visual>
		<visual name="drawer_slider-34">
			<origin xyz="0 0 0" />
			<geometry>
				<mesh filename="textured_objs/original-58.obj" />
			</geometry>
		</visual>
		<visual name="drawer_slider-35">
			<origin xyz="0 0 0" />
			<geometry>
				<mesh filename="textured_objs/original-59.obj" />
			</geometry>
		</visual>
		<visual name="drawer_slider-25">
			<origin xyz="0 0 0" />
			<geometry>
				<mesh filename="textured_objs/original-74.obj" />
			</geometry>
		</visual>
		<visual name="drawer_slider-26">
			<origin xyz="0 0 0" />
			<geometry>
				<mesh filename="textured_objs/original-75.obj" />
			</geometry>
		</visual>
		<collision>
			<origin xyz="0 0 0" />
			<geometry>
				<mesh filename="textured_objs/original-7.obj" />
			</geometry>
		</collision>
		<collision>
			<origin xyz="0 0 0" />
			<geometry>
				<mesh filename="textured_objs/original-6.obj" />
			</geometry>
		</collision>
		<collision>
			<origin xyz="0 0 0" />
			<geometry>
				<mesh filename="textured_objs/original-4.obj" />
			</geometry>
		</collision>
		<collision>
			<origin xyz="0 0 0" />
			<geometry>
				<mesh filename="textured_objs/original-3.obj" />
			</geometry>
		</collision>
		<collision>
			<origin xyz="0 0 0" />
			<geometry>
				<mesh filename="textured_objs/original-15.obj" />
			</geometry>
		</collision>
		<collision>
			<origin xyz="0 0 0" />
			<geometry>
				<mesh filename="textured_objs/original-10.obj" />
			</geometry>
		</collision>
		<collision>
			<origin xyz="0 0 0" />
			<geometry>
				<mesh filename="textured_objs/original-9.obj" />
			</geometry>
		</collision>
		<collision>
			<origin xyz="0 0 0" />
			<geometry>
				<mesh filename="textured_objs/original-12.obj" />
			</geometry>
		</collision>
		<collision>
			<origin xyz="0 0 0" />
			<geometry>
				<mesh filename="textured_objs/original-13.obj" />
			</geometry>
		</collision>
		<collision>
			<origin xyz="0 0 0" />
			<geometry>
				<mesh filename="textured_objs/original-16.obj" />
			</geometry>
		</collision>
		<collision>
			<origin xyz="0 0 0" />
			<geometry>
				<mesh filename="textured_objs/original-14.obj" />
			</geometry>
		</collision>
		<collision>
			<origin xyz="0 0 0" />
			<geometry>
				<mesh filename="textured_objs/original-43.obj" />
			</geometry>
		</collision>
		<collision>
			<origin xyz="0 0 0" />
			<geometry>
				<mesh filename="textured_objs/original-44.obj" />
			</geometry>
		</collision>
		<collision>
			<origin xyz="0 0 0" />
			<geometry>
				<mesh filename="textured_objs/original-27.obj" />
			</geometry>
		</collision>
		<collision>
			<origin xyz="0 0 0" />
			<geometry>
				<mesh filename="textured_objs/original-28.obj" />
			</geometry>
		</collision>
		<collision>
			<origin xyz="0 0 0" />
			<geometry>
				<mesh filename="textured_objs/original-58.obj" />
			</geometry>
		</collision>
		<collision>
			<origin xyz="0 0 0" />
			<geometry>
				<mesh filename="textured_objs/original-59.obj" />
			</geometry>
		</collision>
		<collision>
			<origin xyz="0 0 0" />
			<geometry>
				<mesh filename="textured_objs/original-74.obj" />
			</geometry>
		</collision>
		<collision>
			<origin xyz="0 0 0" />
			<geometry>
				<mesh filename="textured_objs/original-75.obj" />
			</geometry>
		</collision>
	</link>
	<joint name="joint_0" type="fixed">
		<origin rpy="1.570796326794897 0 -1.570796326794897" xyz="0 0 0" />
		<child link="link_0" />
		<parent link="base" />
	</joint>
	<link name="link_1">
		<visual name="handle-46">
			<origin xyz="0 0 0" />
			<geometry>
				<mesh filename="textured_objs/original-46.obj" />
			</geometry>
		</visual>
		<visual name="handle-46">
			<origin xyz="0 0 0" />
			<geometry>
				<mesh filename="textured_objs/original-47.obj" />
			</geometry>
		</visual>
		<visual name="handle-46">
			<origin xyz="0 0 0" />
			<geometry>
				<mesh filename="textured_objs/original-48.obj" />
			</geometry>
		</visual>
		<visual name="drawer_front-49">
			<origin xyz="0 0 0" />
			<geometry>
				<mesh filename="textured_objs/original-41.obj" />
			</geometry>
		</visual>
		<visual name="drawer_front-49">
			<origin xyz="0 0 0" />
			<geometry>
				<mesh filename="textured_objs/original-34.obj" />
			</geometry>
		</visual>
		<visual name="drawer_side-50">
			<origin xyz="0 0 0" />
			<geometry>
				<mesh filename="textured_objs/original-40.obj" />
			</geometry>
		</visual>
		<visual name="drawer_side-51">
			<origin xyz="0 0 0" />
			<geometry>
				<mesh filename="textured_objs/original-39.obj" />
			</geometry>
		</visual>
		<visual name="drawer_back-52">
			<origin xyz="0 0 0" />
			<geometry>
				<mesh filename="textured_objs/original-42.obj" />
			</geometry>
		</visual>
		<visual name="drawer_bottom-53">
			<origin xyz="0 0 0" />
			<geometry>
				<mesh filename="textured_objs/original-37.obj" />
			</geometry>
		</visual>
		<visual name="drawer_bottom-53">
			<origin xyz="0 0 0" />
			<geometry>
				<mesh filename="textured_objs/original-38.obj" />
			</geometry>
		</visual>
		<collision>
			<origin xyz="0 0 0" />
			<geometry>
				<mesh filename="textured_objs/original-46.obj" />
			</geometry>
		</collision>
		<collision>
			<origin xyz="0 0 0" />
			<geometry>
				<mesh filename="textured_objs/original-47.obj" />
			</geometry>
		</collision>
		<collision>
			<origin xyz="0 0 0" />
			<geometry>
				<mesh filename="textured_objs/original-48.obj" />
			</geometry>
		</collision>
		<collision>
			<origin xyz="0 0 0" />
			<geometry>
				<mesh filename="textured_objs/original-41.obj" />
			</geometry>
		</collision>
		<collision>
			<origin xyz="0 0 0" />
			<geometry>
				<mesh filename="textured_objs/original-34.obj" />
			</geometry>
		</collision>
		<collision>
			<origin xyz="0 0 0" />
			<geometry>
				<mesh filename="textured_objs/original-40.obj" />
			</geometry>
		</collision>
		<collision>
			<origin xyz="0 0 0" />
			<geometry>
				<mesh filename="textured_objs/original-39.obj" />
			</geometry>
		</collision>
		<collision>
			<origin xyz="0 0 0" />
			<geometry>
				<mesh filename="textured_objs/original-42.obj" />
			</geometry>
		</collision>
		<collision>
			<origin xyz="0 0 0" />
			<geometry>
				<mesh filename="textured_objs/original-37.obj" />
			</geometry>
		</collision>
		<collision>
			<origin xyz="0 0 0" />
			<geometry>
				<mesh filename="textured_objs/original-38.obj" />
			</geometry>
		</collision>
	</link>
	<joint name="joint_1" type="prismatic">
		<origin xyz="0 0 0" />
		<axis xyz="0 0 1" />
		<child link="link_1" />
		<parent link="link_0" />
		<limit lower="0" upper="0.9" />
	</joint>
	<link name="link_2">
		<visual name="handle-37">
			<origin xyz="0 0 0" />
			<geometry>
				<mesh filename="textured_objs/original-31.obj" />
			</geometry>
		</visual>
		<visual name="handle-37">
			<origin xyz="0 0 0" />
			<geometry>
				<mesh filename="textured_objs/original-30.obj" />
			</geometry>
		</visual>
		<visual name="handle-37">
			<origin xyz="0 0 0" />
			<geometry>
				<mesh filename="textured_objs/original-32.obj" />
			</geometry>
		</visual>
		<visual name="drawer_front-40">
			<origin xyz="0 0 0" />
			<geometry>
				<mesh filename="textured_objs/original-25.obj" />
			</geometry>
		</visual>
		<visual name="drawer_front-40">
			<origin xyz="0 0 0" />
			<geometry>
				<mesh filename="textured_objs/original-18.obj" />
			</geometry>
		</visual>
		<visual name="drawer_side-41">
			<origin xyz="0 0 0" />
			<geometry>
				<mesh filename="textured_objs/original-24.obj" />
			</geometry>
		</visual>
		<visual name="drawer_side-42">
			<origin xyz="0 0 0" />
			<geometry>
				<mesh filename="textured_objs/original-23.obj" />
			</geometry>
		</visual>
		<visual name="drawer_back-43">
			<origin xyz="0 0 0" />
			<geometry>
				<mesh filename="textured_objs/original-26.obj" />
			</geometry>
		</visual>
		<visual name="drawer_bottom-44">
			<origin xyz="0 0 0" />
			<geometry>
				<mesh filename="textured_objs/original-22.obj" />
			</geometry>
		</visual>
		<visual name="drawer_bottom-44">
			<origin xyz="0 0 0" />
			<geometry>
				<mesh filename="textured_objs/original-21.obj" />
			</geometry>
		</visual>
		<collision>
			<origin xyz="0 0 0" />
			<geometry>
				<mesh filename="textured_objs/original-31.obj" />
			</geometry>
		</collision>
		<collision>
			<origin xyz="0 0 0" />
			<geometry>
				<mesh filename="textured_objs/original-30.obj" />
			</geometry>
		</collision>
		<collision>
			<origin xyz="0 0 0" />
			<geometry>
				<mesh filename="textured_objs/original-32.obj" />
			</geometry>
		</collision>
		<collision>
			<origin xyz="0 0 0" />
			<geometry>
				<mesh filename="textured_objs/original-25.obj" />
			</geometry>
		</collision>
		<collision>
			<origin xyz="0 0 0" />
			<geometry>
				<mesh filename="textured_objs/original-18.obj" />
			</geometry>
		</collision>
		<collision>
			<origin xyz="0 0 0" />
			<geometry>
				<mesh filename="textured_objs/original-24.obj" />
			</geometry>
		</collision>
		<collision>
			<origin xyz="0 0 0" />
			<geometry>
				<mesh filename="textured_objs/original-23.obj" />
			</geometry>
		</collision>
		<collision>
			<origin xyz="0 0 0" />
			<geometry>
				<mesh filename="textured_objs/original-26.obj" />
			</geometry>
		</collision>
		<collision>
			<origin xyz="0 0 0" />
			<geometry>
				<mesh filename="textured_objs/original-22.obj" />
			</geometry>
		</collision>
		<collision>
			<origin xyz="0 0 0" />
			<geometry>
				<mesh filename="textured_objs/original-21.obj" />
			</geometry>
		</collision>
	</link>
	<joint name="joint_2" type="prismatic">
		<origin xyz="0 0 0" />
		<axis xyz="0 0 1" />
		<child link="link_2" />
		<parent link="link_0" />
		<limit lower="0" upper="0.9" />
	</joint>
	<link name="link_3">
		<visual name="handle-15">
			<origin xyz="0 0 0" />
			<geometry>
				<mesh filename="textured_objs/original-63.obj" />
			</geometry>
		</visual>
		<visual name="handle-15">
			<origin xyz="0 0 0" />
			<geometry>
				<mesh filename="textured_objs/original-62.obj" />
			</geometry>
		</visual>
		<visual name="handle-15">
			<origin xyz="0 0 0" />
			<geometry>
				<mesh filename="textured_objs/original-64.obj" />
			</geometry>
		</visual>
		<visual name="drawer_front-29">
			<origin xyz="0 0 0" />
			<geometry>
				<mesh filename="textured_objs/original-60.obj" />
			</geometry>
		</visual>
		<visual name="drawer_front-29">
			<origin xyz="0 0 0" />
			<geometry>
				<mesh filename="textured_objs/original-56.obj" />
			</geometry>
		</visual>
		<visual name="drawer_side-30">
			<origin xyz="0 0 0" />
			<geometry>
				<mesh filename="textured_objs/original-55.obj" />
			</geometry>
		</visual>
		<visual name="drawer_side-31">
			<origin xyz="0 0 0" />
			<geometry>
				<mesh filename="textured_objs/original-54.obj" />
			</geometry>
		</visual>
		<visual name="drawer_back-32">
			<origin xyz="0 0 0" />
			<geometry>
				<mesh filename="textured_objs/original-57.obj" />
			</geometry>
		</visual>
		<visual name="drawer_bottom-33">
			<origin xyz="0 0 0" />
			<geometry>
				<mesh filename="textured_objs/original-53.obj" />
			</geometry>
		</visual>
		<visual name="drawer_bottom-33">
			<origin xyz="0 0 0" />
			<geometry>
				<mesh filename="textured_objs/original-52.obj" />
			</geometry>
		</visual>
		<collision>
			<origin xyz="0 0 0" />
			<geometry>
				<mesh filename="textured_objs/original-63.obj" />
			</geometry>
		</collision>
		<collision>
			<origin xyz="0 0 0" />
			<geometry>
				<mesh filename="textured_objs/original-62.obj" />
			</geometry>
		</collision>
		<collision>
			<origin xyz="0 0 0" />
			<geometry>
				<mesh filename="textured_objs/original-64.obj" />
			</geometry>
		</collision>
		<collision>
			<origin xyz="0 0 0" />
			<geometry>
				<mesh filename="textured_objs/original-60.obj" />
			</geometry>
		</collision>
		<collision>
			<origin xyz="0 0 0" />
			<geometry>
				<mesh filename="textured_objs/original-56.obj" />
			</geometry>
		</collision>
		<collision>
			<origin xyz="0 0 0" />
			<geometry>
				<mesh filename="textured_objs/original-55.obj" />
			</geometry>
		</collision>
		<collision>
			<origin xyz="0 0 0" />
			<geometry>
				<mesh filename="textured_objs/original-54.obj" />
			</geometry>
		</collision>
		<collision>
			<origin xyz="0 0 0" />
			<geometry>
				<mesh filename="textured_objs/original-57.obj" />
			</geometry>
		</collision>
		<collision>
			<origin xyz="0 0 0" />
			<geometry>
				<mesh filename="textured_objs/original-53.obj" />
			</geometry>
		</collision>
		<collision>
			<origin xyz="0 0 0" />
			<geometry>
				<mesh filename="textured_objs/original-52.obj" />
			</geometry>
		</collision>
	</link>
	<joint name="joint_3" type="prismatic">
		<origin xyz="0 0 0" />
		<axis xyz="0 0 1" />
		<child link="link_3" />
		<parent link="link_0" />
		<limit lower="0" upper="0.9" />
	</joint>
	<link name="link_4">
		<visual name="handle-11">
			<origin xyz="0 0 0" />
			<geometry>
				<mesh filename="textured_objs/original-78.obj" />
			</geometry>
		</visual>
		<visual name="handle-11">
			<origin xyz="0 0 0" />
			<geometry>
				<mesh filename="textured_objs/original-79.obj" />
			</geometry>
		</visual>
		<visual name="handle-11">
			<origin xyz="0 0 0" />
			<geometry>
				<mesh filename="textured_objs/original-80.obj" />
			</geometry>
		</visual>
		<visual name="drawer_front-12">
			<origin xyz="0 0 0" />
			<geometry>
				<mesh filename="textured_objs/original-72.obj" />
			</geometry>
		</visual>
		<visual name="drawer_front-12">
			<origin xyz="0 0 0" />
			<geometry>
				<mesh filename="textured_objs/original-76.obj" />
			</geometry>
		</visual>
		<visual name="drawer_side-16">
			<origin xyz="0 0 0" />
			<geometry>
				<mesh filename="textured_objs/original-70.obj" />
			</geometry>
		</visual>
		<visual name="drawer_side-17">
			<origin xyz="0 0 0" />
			<geometry>
				<mesh filename="textured_objs/original-71.obj" />
			</geometry>
		</visual>
		<visual name="drawer_back-18">
			<origin xyz="0 0 0" />
			<geometry>
				<mesh filename="textured_objs/original-73.obj" />
			</geometry>
		</visual>
		<visual name="drawer_bottom-19">
			<origin xyz="0 0 0" />
			<geometry>
				<mesh filename="textured_objs/original-69.obj" />
			</geometry>
		</visual>
		<visual name="drawer_bottom-19">
			<origin xyz="0 0 0" />
			<geometry>
				<mesh filename="textured_objs/original-68.obj" />
			</geometry>
		</visual>
		<collision>
			<origin xyz="0 0 0" />
			<geometry>
				<mesh filename="textured_objs/original-78.obj" />
			</geometry>
		</collision>
		<collision>
			<origin xyz="0 0 0" />
			<geometry>
				<mesh filename="textured_objs/original-79.obj" />
			</geometry>
		</collision>
		<collision>
			<origin xyz="0 0 0" />
			<geometry>
				<mesh filename="textured_objs/original-80.obj" />
			</geometry>
		</collision>
		<collision>
			<origin xyz="0 0 0" />
			<geometry>
				<mesh filename="textured_objs/original-72.obj" />
			</geometry>
		</collision>
		<collision>
			<origin xyz="0 0 0" />
			<geometry>
				<mesh filename="textured_objs/original-76.obj" />
			</geometry>
		</collision>
		<collision>
			<origin xyz="0 0 0" />
			<geometry>
				<mesh filename="textured_objs/original-70.obj" />
			</geometry>
		</collision>
		<collision>
			<origin xyz="0 0 0" />
			<geometry>
				<mesh filename="textured_objs/original-71.obj" />
			</geometry>
		</collision>
		<collision>
			<origin xyz="0 0 0" />
			<geometry>
				<mesh filename="textured_objs/original-73.obj" />
			</geometry>
		</collision>
		<collision>
			<origin xyz="0 0 0" />
			<geometry>
				<mesh filename="textured_objs/original-69.obj" />
			</geometry>
		</collision>
		<collision>
			<origin xyz="0 0 0" />
			<geometry>
				<mesh filename="textured_objs/original-68.obj" />
			</geometry>
		</collision>
	</link>
	<joint name="joint_4" type="prismatic">
		<origin xyz="0 0 0" />
		<axis xyz="0 0 1" />
		<child link="link_4" />
		<parent link="link_0" />
		<limit lower="0" upper="0.9" />
	</joint>
</robot>