<?xml version='1.0' encoding='utf-8'?>
<robot name="partnet_6570cb4c8e3d4f855db89a6b4ebc7e35-0">
	<link name="base" />
	<link name="link_0">
		<visual name="leg-1">
			<origin xyz="0.45507735704626007 -0.06206694441273264 -0.10080566593443455" />
			<geometry>
				<mesh filename="textured_objs/original-12.obj" />
			</geometry>
		</visual>
		<visual name="leg-1">
			<origin xyz="0.45507735704626007 -0.06206694441273264 -0.10080566593443455" />
			<geometry>
				<mesh filename="textured_objs/original-15.obj" />
			</geometry>
		</visual>
		<collision>
			<origin xyz="0.45507735704626007 -0.06206694441273264 -0.10080566593443455" />
			<geometry>
				<mesh filename="textured_objs/original-12.obj" />
			</geometry>
		</collision>
		<collision>
			<origin xyz="0.45507735704626007 -0.06206694441273264 -0.10080566593443455" />
			<geometry>
				<mesh filename="textured_objs/original-15.obj" />
			</geometry>
		</collision>
	</link>
	<joint name="joint_0" type="revolute">
		<origin xyz="-0.45507735704626007 0.06206694441273264 0.10080566593443455" />
		<axis xyz="0 -1 0" />
		<child link="link_0" />
		<parent link="link_2" />
		<limit lower="-0.0" upper="1.262920246743096" />
	</joint>
	<link name="link_1">
		<visual name="leg-2">
			<origin xyz="-0.4548917935170296 -0.07345574217462492 -0.0886938003730054" />
			<geometry>
				<mesh filename="textured_objs/original-7.obj" />
			</geometry>
		</visual>
		<visual name="leg-2">
			<origin xyz="-0.4548917935170296 -0.07345574217462492 -0.0886938003730054" />
			<geometry>
				<mesh filename="textured_objs/original-10.obj" />
			</geometry>
		</visual>
		<collision>
			<origin xyz="-0.4548917935170296 -0.07345574217462492 -0.0886938003730054" />
			<geometry>
				<mesh filename="textured_objs/original-7.obj" />
			</geometry>
		</collision>
		<collision>
			<origin xyz="-0.4548917935170296 -0.07345574217462492 -0.0886938003730054" />
			<geometry>
				<mesh filename="textured_objs/original-10.obj" />
			</geometry>
		</collision>
	</link>
	<joint name="joint_1" type="revolute">
		<origin xyz="0.4548917935170296 0.07345574217462492 0.0886938003730054" />
		<axis xyz="0 1 0" />
		<child link="link_1" />
		<parent link="link_2" />
		<limit lower="0.0" upper="1.5205308443374599" />
	</joint>
	<link name="link_2">
		<visual name="base_body-3">
			<origin xyz="0 0 0" />
			<geometry>
				<mesh filename="textured_objs/original-4.obj" />
			</geometry>
		</visual>
		<visual name="base_body-3">
			<origin xyz="0 0 0" />
			<geometry>
				<mesh filename="textured_objs/original-2.obj" />
			</geometry>
		</visual>
		<visual name="base_body-3">
			<origin xyz="0 0 0" />
			<geometry>
				<mesh filename="textured_objs/original-16.obj" />
			</geometry>
		</visual>
		<visual name="base_body-3">
			<origin xyz="0 0 0" />
			<geometry>
				<mesh filename="textured_objs/original-8.obj" />
			</geometry>
		</visual>
		<visual name="base_body-3">
			<origin xyz="0 0 0" />
			<geometry>
				<mesh filename="textured_objs/original-13.obj" />
			</geometry>
		</visual>
		<visual name="base_body-3">
			<origin xyz="0 0 0" />
			<geometry>
				<mesh filename="textured_objs/original-9.obj" />
			</geometry>
		</visual>
		<visual name="base_body-3">
			<origin xyz="0 0 0" />
			<geometry>
				<mesh filename="textured_objs/original-5.obj" />
			</geometry>
		</visual>
		<visual name="base_body-3">
			<origin xyz="0 0 0" />
			<geometry>
				<mesh filename="textured_objs/original-17.obj" />
			</geometry>
		</visual>
		<visual name="base_body-3">
			<origin xyz="0 0 0" />
			<geometry>
				<mesh filename="textured_objs/original-1.obj" />
			</geometry>
		</visual>
		<visual name="base_body-3">
			<origin xyz="0 0 0" />
			<geometry>
				<mesh filename="textured_objs/original-14.obj" />
			</geometry>
		</visual>
		<collision>
			<origin xyz="0 0 0" />
			<geometry>
				<mesh filename="textured_objs/original-4.obj" />
			</geometry>
		</collision>
		<collision>
			<origin xyz="0 0 0" />
			<geometry>
				<mesh filename="textured_objs/original-2.obj" />
			</geometry>
		</collision>
		<collision>
			<origin xyz="0 0 0" />
			<geometry>
				<mesh filename="textured_objs/original-16.obj" />
			</geometry>
		</collision>
		<collision>
			<origin xyz="0 0 0" />
			<geometry>
				<mesh filename="textured_objs/original-8.obj" />
			</geometry>
		</collision>
		<collision>
			<origin xyz="0 0 0" />
			<geometry>
				<mesh filename="textured_objs/original-13.obj" />
			</geometry>
		</collision>
		<collision>
			<origin xyz="0 0 0" />
			<geometry>
				<mesh filename="textured_objs/original-9.obj" />
			</geometry>
		</collision>
		<collision>
			<origin xyz="0 0 0" />
			<geometry>
				<mesh filename="textured_objs/original-5.obj" />
			</geometry>
		</collision>
		<collision>
			<origin xyz="0 0 0" />
			<geometry>
				<mesh filename="textured_objs/original-17.obj" />
			</geometry>
		</collision>
		<collision>
			<origin xyz="0 0 0" />
			<geometry>
				<mesh filename="textured_objs/original-1.obj" />
			</geometry>
		</collision>
		<collision>
			<origin xyz="0 0 0" />
			<geometry>
				<mesh filename="textured_objs/original-14.obj" />
			</geometry>
		</collision>
	</link>
	<joint name="joint_2" type="fixed">
		<origin rpy="1.570796326794897 0 -1.570796326794897" xyz="0 0 0" />
		<child link="link_2" />
		<parent link="base" />
	</joint>
</robot>